[2024-10-26T08:40:02.950132+0530] [0:00:00.889040] [script.py: 21] > Starting script
[2024-10-26T08:40:03.812444+0530] [0:00:01.751352] [mail.py: 76] > Email has been sent successfully
[2024-10-26T08:40:03.820817+0530] [0:00:01.759725] [script.py: 38] > Loading data
Traceback (most recent call last):
  File "/home/asyncxeno/Dev/review-monitoring/./script.py", line 44, in <module>
    driver = get_chromedriver_without_proxy()
  File "/home/asyncxeno/Dev/review-monitoring/utils/selenium_utils.py", line 17, in wrapper
    driver: webdriver.Chrome = f(*args, **kwargs)
  File "/home/asyncxeno/Dev/review-monitoring/utils/selenium_utils.py", line 55, in get_chromedriver_without_proxy
    driver = uc.Chrome(options=chrome_options, driver_executable_path=ChromeDriverManager().install())
  File "/home/asyncxeno/Dev/review-monitoring/venv/lib/python3.10/site-packages/undetected_chromedriver/__init__.py", line 466, in __init__
    super(Chrome, self).__init__(
  File "/home/asyncxeno/Dev/review-monitoring/venv/lib/python3.10/site-packages/selenium/webdriver/chrome/webdriver.py", line 45, in __init__
    super().__init__(
  File "/home/asyncxeno/Dev/review-monitoring/venv/lib/python3.10/site-packages/selenium/webdriver/chromium/webdriver.py", line 61, in __init__
    super().__init__(command_executor=executor, options=options)
  File "/home/asyncxeno/Dev/review-monitoring/venv/lib/python3.10/site-packages/selenium/webdriver/remote/webdriver.py", line 208, in __init__
    self.start_session(capabilities)
  File "/home/asyncxeno/Dev/review-monitoring/venv/lib/python3.10/site-packages/undetected_chromedriver/__init__.py", line 724, in start_session
    super(selenium.webdriver.chrome.webdriver.WebDriver, self).start_session(
  File "/home/asyncxeno/Dev/review-monitoring/venv/lib/python3.10/site-packages/selenium/webdriver/remote/webdriver.py", line 292, in start_session
    response = self.execute(Command.NEW_SESSION, caps)["value"]
  File "/home/asyncxeno/Dev/review-monitoring/venv/lib/python3.10/site-packages/selenium/webdriver/remote/webdriver.py", line 347, in execute
    self.error_handler.check_response(response)
  File "/home/asyncxeno/Dev/review-monitoring/venv/lib/python3.10/site-packages/selenium/webdriver/remote/errorhandler.py", line 229, in check_response
    raise exception_class(message, screen, stacktrace)
selenium.common.exceptions.SessionNotCreatedException: Message: session not created: cannot connect to chrome at 127.0.0.1:48309
from chrome not reachable
Stacktrace:
#0 0x5dca438fb10a <unknown>
#1 0x5dca434162bd <unknown>
#2 0x5dca434024bf <unknown>
#3 0x5dca4345156c <unknown>
#4 0x5dca43447392 <unknown>
#5 0x5dca43493156 <unknown>
#6 0x5dca434927a6 <unknown>
#7 0x5dca43486db3 <unknown>
#8 0x5dca43455c10 <unknown>
#9 0x5dca43456bee <unknown>
#10 0x5dca438c739b <unknown>
#11 0x5dca438cb338 <unknown>
#12 0x5dca438b4ebc <unknown>
#13 0x5dca438cbeb7 <unknown>
#14 0x5dca4389a10f <unknown>
#15 0x5dca438e9828 <unknown>
#16 0x5dca438e99f0 <unknown>
#17 0x5dca438f9f86 <unknown>
#18 0x7f210d094ac3 <unknown>

